<?xml version='1.0'?>

<robot name="simple_arm" 
  xmlns:xacro="http://www.ros.org/wiki/xacro">

  <!-- Used for fixing robot to Gazebo 'base_link' -->
  <link name="world"/>

  <joint name="fixed" type="fixed">
    <parent link="world"/>
    <child link="arm_footprint"/>
  </joint>

  <!-- footprint tile -->
  <link name='arm_footprint'>
    <inertial>
      <mass value="0.1"/>
      <origin xyz="0.0 0 0" rpy="0 0 0"/>
      <inertia ixx="10" ixy="0.0" ixz="0.0" iyy="10" iyz="0.0" izz="10"/>
    </inertial>

    <collision name='arm_footprint_collision'>
      <origin xyz="0 0 0" rpy="0 0 0"/>
      <geometry>
        <box size="0.15 .095 .003"/>
      </geometry>
    </collision>

    <visual name='arm_footprint_visual'>
      <origin xyz="0 0 0" rpy="0 0 0"/>
      <geometry>
        <box size="0.15 .095 .003"/>
      </geometry>
    </visual>
  </link>
  <!-- begin base block -->
  <joint name="arm_footprint_base_block_joint" type="fixed">
    <origin xyz="0.033 0 0.015"/>
    <child link="base_block" />
    <parent link="arm_footprint" />
  </joint>

  <link name='base_block'>
    <inertial>
      <mass value="0.05" />
      <inertia ixx="10" ixy="0.0" ixz="0.0" iyy="10" iyz="0.0" izz="10"/>
    </inertial>
    <visual name='base_block_visual'>
      <origin xyz="0 0 0" rpy="0 0 0"/>
      <geometry>
        <box size="0.06 0.06 0.028"/>
      </geometry>
    </visual>
    <collision name='base_block_collision'>
      <origin xyz="0 0 0" rpy="0 0 0"/>
      <geometry>
        <box size="0.06 0.06 0.028"/>
      </geometry>
    </collision>

  </link>
  <!-- end base block -->
  <!-- begin rotating block -->
  <joint name="base_block_rotating_block_joint" type="revolute">
    <limit lower="-1.54" upper="1.54" effort="10" velocity="3"/>
    <axis xyz="0 0 1"/>
    <origin xyz="0 0 0.019" rpy="0 0 0" />
    <child link="rotating_block"/>
    <parent link="base_block"/>
  </joint>
  <link name='rotating_block'>
    <inertial>
      <mass value="0.05" />
      <inertia ixx="10" ixy="0.0" ixz="0.0" iyy="10" iyz="0.0" izz="10"/>
    </inertial>

    <visual name='rotating_block_visual_right'>
      <origin xyz="0 0.0285 0.02" rpy="0 0 0"/>
      <geometry>
        <box size="0.06 0.003 0.04"/>
      </geometry>
    </visual>

    <visual name='rotating_block_visual_left'>
      <origin xyz="0 -0.0285 0.02" rpy="0 0 0"/>
      <geometry>
        <box size="0.06 0.003 0.04"/>
      </geometry>
    </visual>

    <visual name='rotating_block_visual_base'>
      <origin xyz="0 0 0" rpy="0 0 0"/>
      <geometry>
        <box size="0.06 0.06 0.003"/>
      </geometry>
    </visual>
    <collision name='rotating_block_collision_right'>
      <origin xyz="0 0.0285 0.02" rpy="0 0 0"/>
      <geometry>
        <box size="0.06 0.003 0.04"/>
      </geometry>
    </collision>

    <collision name='rotating_block_collision_left'>
      <origin xyz="0 -0.0285 0.02" rpy="0 0 0"/>
      <geometry>
        <box size="0.06 0.003 0.04"/>
      </geometry>
    </collision>

    <collision name='rotating_block_collision_base'>
      <origin xyz="0 0 0" rpy="0 0 0"/>
      <geometry>
        <box size="0.06 0.06 0.003"/>
      </geometry>
    </collision>


    <visual name='rotating_block_vertical_arm_axis'>
      <!-- no collission for this part as it's just for our visual reference -->
      <origin xyz="-0.023 0 0.01825" rpy="1.573301 0 0"/>
      <geometry>
        <cylinder length="0.06" radius="0.005"/>
      </geometry>
    </visual>

  </link>
  <!-- end rotating block -->
  <!-- begin vertical arm -->
  <joint name="rotating_block_vertical_arm_joint" type="revolute">
    <limit lower="-1.54" upper="0.6" effort="10" velocity="3"/>
    <axis xyz="0 1 0"/>
    <origin xyz="-0.023 0.008 0.01825" rpy="0 0 0"/>
    <child link="vertical_arm"/>
    <parent link="rotating_block"/>
    <dynamics friction="0.7"/>
  </joint>

  <link name='vertical_arm'>
    <inertial>
      <mass value="0.05" />
      <inertia ixx="10" ixy="0.0" ixz="0.0" iyy="10" iyz="0.0" izz="10"/>
    </inertial>
    <visual name='vertical_arm_visual'>
      <origin xyz="0 0 0.0395" rpy="0 0 0"/>
      <geometry>
        <box size="0.012 0.025 0.087"/>
      </geometry>
    </visual>
    <collision name='vertical_arm_collision'>
      <origin xyz="0 0 0.0395" rpy="0 0 0"/>
      <geometry>
        <box size="0.012 0.025 0.087"/>
      </geometry>
    </collision>

  </link>
  <!-- end vertical arm -->
  <!-- begin forearm -->
  <joint name="vertical_arm_forearm_joint" type="revolute">
    <limit lower="-.78" upper="1.7" effort="10" velocity="3"/>
    <axis xyz="0 1 0"/>
    <origin xyz="0 0.0 0.084" rpy="0 1 0"/>
    <parent link="vertical_arm"/>
    <child link="forearm"/>
    <dynamics friction="0.7"/>
  </joint>

  <link name='forearm'>
    <inertial>
      <mass value="0.05" />
      <inertia ixx="10" ixy="0.0" ixz="0.0" iyy="10" iyz="0.0" izz="10"/>
    </inertial>
    <visual name='forearm_visual'>
      <origin xyz="0 0 -0.037" rpy="0 0 0"/>
      <geometry>
        <box size="0.012 0.0305 0.088"/>
      </geometry>
    </visual>
    <collision name='forearm_collision'>
      <origin xyz="0 0 -0.037" rpy="0 0 0"/>
      <geometry>
        <box size="0.012 0.0305 0.088"/>
      </geometry>
    </collision>
  </link>
  <!-- end forearm -->
  <!-- begin actuator -->
  <joint name="actuator_forearm_joint" type="revolute">
    <limit lower="-.78" upper="1.7" effort="10" velocity="3"/>
    <axis xyz="0 1 0"/>
    <origin xyz="0 0 -0.0845" rpy="0 0.57 0"/>
    <child link="actuator_body"/>
    <parent link="forearm"/>
    <dynamics friction="0.7"/>
  </joint>

  <link name='actuator_body'>
    <inertial>
      <mass value="0.05" />
      <inertia ixx="10" ixy="0.0" ixz="0.0" iyy="10" iyz="0.0" izz="10"/>
    </inertial>
    <visual name='actuator_body_visual'>
      <origin xyz="0 0 -0.008" rpy="0 0 0"/>
      <geometry>
        <box size="0.01 0.024 0.050"/>
      </geometry>
    </visual>
    <collision name='actuator_body_collision'>
      <origin xyz="0 0 -0.008" rpy="0 0 0"/>
      <geometry>
        <box size="0.01 0.024 0.050"/>
      </geometry>
    </collision>

  </link>
  <joint name="left_gripper_actuator_body" type="revolute">
    <limit lower="-.78" upper="0" effort="10" velocity="3"/>
    <axis xyz="1 0 0"/>
    <origin xyz="0 -0.0109 -0.029 " rpy="0 0 0"/>
    <parent link="actuator_body"/>
    <child link="left_gripper"/>
  </joint>

  <link name='left_gripper'>
    <inertial>
      <mass value="0.005" />
      <inertia ixx="10" ixy="0.0" ixz="0.0" iyy="10" iyz="0.0" izz="10"/>
    </inertial>
    <visual name='left_gripper_visual'>
      <origin xyz="0 0 -0.0205" rpy="0 0 0"/>
      <geometry>
        <box size="0.003 0.01 0.041"/>
      </geometry>
    </visual>
    <visual name='left_gripper_tip_visual'>
      <origin xyz="0 .0079 -0.035" rpy="0 0 0"/>
      <geometry>
        <box size="0.003 0.005 0.01"/>
      </geometry>
    </visual>
    <collision name='left_gripper_collision'>
      <origin xyz="0 0 -0.0205" rpy="0 0 0"/>
      <geometry>
        <box size="0.003 0.01 0.041"/>
      </geometry>
    </collision>
    <collision name='left_gripper_tip_collision'>
      <origin xyz="0 .0079 -0.035" rpy="0 0 0"/>
      <geometry>
        <box size="0.003 0.005 0.01"/>
      </geometry>
    </collision>
  </link>
  <joint name="right_gripper_actuator_body" type="revolute">
    <limit lower="0" upper="0.78" effort="10" velocity="3"/>
    <axis xyz="1 0 0"/>
    <origin xyz="0 0.0109 -0.029 " rpy="0 0 0"/>
    <parent link="actuator_body"/>
    <child link="right_gripper"/>
  </joint>

  <link name='right_gripper'>
    <inertial>
      <mass value="0.005" />
      <inertia ixx="10" ixy="0.0" ixz="0.0" iyy="10" iyz="0.0" izz="10"/>
    </inertial>
    <visual name='right_gripper_side_visual'>
      <origin xyz="0 0 -0.0205" rpy="0 0 0"/>
      <geometry>
        <box size="0.003 0.01 0.041"/>
      </geometry>
    </visual>
    <visual name='right_gripper_tip_visual'>
      <origin xyz="0 -.0079 -0.035" rpy="0 0 0"/>
      <geometry>
        <box size="0.003 0.005 0.01"/>
      </geometry>
    </visual>
    <collision name='right_gripper_side_collision'>
      <origin xyz="0 0 -0.0205" rpy="0 0 0"/>
      <geometry>
        <box size="0.003 0.01 0.041"/>
      </geometry>
    </collision>
    <collision name='right_gripper_tip_collision'>
      <origin xyz="0 -.0079 -0.035" rpy="0 0 0"/>
      <geometry>
        <box size="0.003 0.005 0.01"/>
      </geometry>
    </collision>
  </link>

  <!-- end actuator-->


</robot>